Workbook

Sheet Assumptions
A1: ФИНАНСОВАЯ МОДЕЛЬ — ПРЕДПОСЫЛКИ
A2: Синие значения — редактируемые предпосылки. Чёрные — формулы.
A4: ТАРИФЫ И ПРОДУКТ
A5: Параметр | B5: Значение | C5: Ед. | D5: Комментарий
A6: Цена тарифа Старт | B6: 1490 | C6: ₽/мес | D6: Базовый тариф
A7: Цена тарифа Pro | B7: 2490 | C7: ₽/мес | D7: Якорный тариф
A8: Цена тарифа Business | B8: 3990 | C8: ₽/мес/магазин | D8: От 3 точек
A9: Доля Старт среди платящих | B9: 0.5 | C9: %
A10: Доля Pro среди платящих | B10: 0.35 | C10: %
A11: Доля Business среди платящих | B11: 0.15 | C11: % | D11: Сумма долей = 100%
A13: Blended ARPU (платящие) | B13: =B6*B9+B7*B10+B8*B11 -> 2215 | C13: ₽/мес | D13: Формула: средневзвешенная
A15: РОСТ КЛИЕНТОВ (платящие)
A16: Параметр | B16: Значение | C16: Ед. | D16: Комментарий
A17: Клиенты на M3 (старт продаж) | B17: 20 | C17: клиентов | D17: Из плана
A18: Клиенты на M9 (break-even) | B18: 100 | C18: клиентов | D18: Точка безубыточности
A19: Клиенты на M12 (конец Y1) | B19: 400 | C19: клиентов | D19: Из плана
A20: Клиенты на M24 (конец Y2) | B20: 2500 | C20: клиентов | D20: Из плана
A21: Клиенты на M36 (конец Y3) | B21: 10741 | C21: клиентов | D21: 1% SOM
A22: Месячный churn | B22: 0.04 | C22: % | D22: ≤5%/мес из плана
A24: ПЕРЕМЕННЫЕ РАСХОДЫ (на клиента)
A25: Параметр | B25: Значение | C25: Ед. | D25: Комментарий
A26: LLM-затраты на клиента (медиана) | B26: 330 | C26: ₽/мес/клиент | D26: Sonnet+Haiku+Gemini c кешем
A27: Эквайринг (% от выручки) | B27: 0.025 | C27: % | D27: Стандарт 2.5%
A28: Партнёрская комиссия (% от выручки) | B28: 0.15 | C28: % | D28: 15% по плану
A30: ИНФРАСТРУКТУРА (фикс. часть, ₽/мес)
A31: Статья | B31: Y1 avg | C31: Y2 avg | D31: Y3 avg
A32: Compute (Yandex Cloud / Selectel) | B32: 25000 | C32: 100000 | D32: 350000
A33: Object Storage (S3) | B33: 4000 | C33: 12000 | D33: 50000
A34: Managed PostgreSQL | B34: 9000 | C34: 30000 | D34: 80000
A35: Мониторинг (Sentry, Grafana) | B35: 6000 | C35: 15000 | D35: 30000
A36: Email/SMS уведомления | B36: 5000 | C36: 20000 | D36: 60000
A37: Domain, CDN, SSL, backup | B37: 3000 | C37: 8000 | D37: 20000
A38: Dev-tools (GitHub, Linear, Notion) | B38: 5000 | C38: 12000 | D38: 25000
A39: ИТОГО инфраструктура | B39: =SUM(B32:B38) -> 57000 | C39: =SUM(C32:C38) -> 197000 | D39: =SUM(D32:D38) -> 615000
A41: ФОТ И ВЗНОСЫ (₽/мес для компании)
A42: Статья | B42: Y1 avg | C42: Y2 avg | D42: Y3 avg
A43: ФОТ (зарплата до НДФЛ) | B43: 50000 | C43: 240000 | D43: 1620000
A44: Страховые взносы МСП | B44: 14000 | C44: 50000 | D44: 240000
A45: ИТОГО ФОТ + взносы | B45: =SUM(B43:B44) -> 64000 | C45: =SUM(C43:C44) -> 290000 | D45: =SUM(D43:D44) -> 1860000
A47: G&A — АДМИНИСТРАТИВНЫЕ РАСХОДЫ (₽/мес)
...

Sheet P&L Monthly
A1: ПОМЕСЯЧНЫЙ P&L — 36 МЕСЯЦЕВ
A2: Месяц | B2: M1 | C2: M2 | D2: M3 | E2: M4 | F2: M5 | G2: M6 | H2: M7 | I2: M8 | J2: M9 | K2: M10 | L2: M11 | M2: M12 | N2: M13 | O2: M14 | P2: M15 | Q2: M16 | R2: M17 | S2: M18 | T2: M19 | U2: M20 | V2: M21 | W2: M22 | X2: M23 | Y2: M24 | Z2: M25 | AA2: M26 | AB2: M27 | AC2: M28 | AD2: M29 | AE2: M30 | AF2: M31 | AG2: M32 | AH2: M33 | AI2: M34 | AJ2: M35 | AK2: M36
A3: Год | B3: Y1 | C3: Y1 | D3: Y1 | E3: Y1 | F3: Y1 | G3: Y1 | H3: Y1 | I3: Y1 | J3: Y1 | K3: Y1 | L3: Y1 | M3: Y1 | N3: Y2 | O3: Y2 | P3: Y2 | Q3: Y2 | R3: Y2 | S3: Y2 | T3: Y2 | U3: Y2 | V3: Y2 | W3: Y2 | X3: Y2 | Y3: Y2 | Z3: Y3 | AA3: Y3 | AB3: Y3 | AC3: Y3 | AD3: Y3 | AE3: Y3 | AF3: Y3 | AG3: Y3 | AH3: Y3 | AI3: Y3 | AJ3: Y3 | AK3: Y3
A5: КЛИЕНТЫ И ВЫРУЧКА
A6: Активные клиенты | B6: =ROUND(Assumptions!$B$17*1/3,0) -> 7 | C6: =ROUND(Assumptions!$B$17*2/3,0) -> 13 | D6: =ROUND(Assumptions!$B$17*3/3,0) -> 20 | E6: =ROUND(Assumptions!$B$17+(Assumptions!$B$18-Assumptions!$B$17)*(4-3)/6,0) -> 33 | F6: =ROUND(Assumptions!$B$17+(Assumptions!$B$18-Assumptions!$B$17)*(5-3)/6,0) -> 47 | G6: =ROUND(Assumptions!$B$17+(Assumptions!$B$18-Assumptions!$B$17)*(6-3)/6,0) -> 60 | H6: =ROUND(Assumptions!$B$17+(Assumptions!$B$18-Assumptions!$B$17)*(7-3)/6,0) -> 73 | I6: =ROUND(Assumptions!$B$17+(Assumptions!$B$18-Assumptions!$B$17)*(8-3)/6,0) -> 87 | J6: =ROUND(Assumptions!$B$17+(Assumptions!$B$18-Assumptions!$B$17)*(9-3)/6,0) -> 100 | K6: =ROUND(Assumptions!$B$18+(Assumptions!$B$19-Assumptions!$B$18)*(10-9)/3,0) -> 200 | L6: =ROUND(Assumptions!$B$18+(Assumptions!$B$19-Assumptions!$B$18)*(11-9)/3,0) -> 300 | M6: =ROUND(Assumptions!$B$18+(Assumptions!$B$19-Assumptions!$B$18)*(12-9)/3,0) -> 400 | N6: =ROUND(Assumptions!$B$19+(Assumptions!$B$20-Assumptions!$B$19)*(13-12)/12,0) -> 575 | O6: =ROUND(Assumptions!$B$19+(Assumptions!$B$20-Assumptions!$B$19)*(14-12)/12,0) -> 750 | P6: =ROUND(Assumptions!$B$19+(Assumptions!$B$20-Assumptions!$B$19)*(15-12)/12,0) -> 925 | Q6: =ROUND(Assumptions!$B$19+(Assumptions!$B$20-Assumptions!$B$19)*(16-12)/12,0) -> 1100 | R6: =ROUND(Assumptions!$B$19+(Assumptions!$B$20-Assumptions!$B$19)*(17-12)/12,0) -> 1275 | S6: =ROUND(Assumptions!$B$19+(Assumptions!$B$20-Assumptions!$B$19)*(18-12)/12,0) -> 1450 | T6: =ROUND(Assumptions!$B$19+(Assumptions!$B$20-Assumptions!$B$19)*(19-12)/12,0) -> 1625 | U6: =ROUND(Assumptions!$B$19+(Assumptions!$B$20-Assumptions!$B$19)*(20-12)/12,0) -> 1800 | V6: =ROUND(Assumptions!$B$19+(Assumptions!$B$20-Assumptions!$B$19)*(21-12)/12,0) -> 1975 | W6: =ROUND(Assumptions!$B$19+(Assumptions!$B$20-Assumptions!$B$19)*(22-12)/12,0) -> 2150 | X6: =ROUND(Assumptions!$B$19+(Assumptions!$B$20-Assumptions!$B$19)*(23-12)/12,0) -> 2325 | Y6: =ROUND(Assumptions!$B$19+(Assumptions!$B$20-Assumptions!$B$19)*(24-12)/12,0) -> 2500 | Z6: =ROUND(Assumptions!$B$20+(Assumptions!$B$21-Assumptions!$B$20)*(25-24)/12,0) -> 3187 | AA6: =ROUND(Assumptions!$B$20+(Assumptions!$B$21-Assumptions!$B$20)*(26-24)/12,0) -> 3874 | AB6: =ROUND(Assumptions!$B$20+(Assumptions!$B$21-Assumptions!$B$20)*(27-24)/12,0) -> 4560 | AC6: =ROUND(Assumptions!$B$20+(Assumptions!$B$21-Assumptions!$B$20)*(28-24)/12,0) -> 5247 | AD6: =ROUND(Assumptions!$B$20+(Assumptions!$B$21-Assumptions!$B$20)*(29-24)/12,0) -> 5934 | AE6: =ROUND(Assumptions!$B$20+(Assumptions!$B$21-Assumptions!$B$20)*(30-24)/12,0) -> 6621 | AF6: =ROUND(Assumptions!$B$20+(Assumptions!$B$21-Assumptions!$B$20)*(31-24)/12,0) -> 7307 | AG6: =ROUND(Assumptions!$B$20+(Assumptions!$B$21-Assumptions!$B$20)*(32-24)/12,0) -> 7994 | AH6: =ROUND(Assumptions!$B$20+(Assumptions!$B$21-Assumptions!$B$20)*(33-24)/12,0) -> 8681 | AI6: =ROUND(Assumptions!$B$20+(Assumptions!$B$21-Assumptions!$B$20)*(34-24)/12,0) -> 9368 | AJ6: =ROUND(Assumptions!$B$20+(Assumptions!$B$21-Assumptions!$B$20)*(35-24)/12,0) -> 10054 | AK6: =ROUND(Assumptions!$B$20+(Assumptions!$B$21-Assumptions!$B$20)*(36-24)/12,0) -> 10741
A7: Выручка (₽) | B7: =B6*Assumptions!$B$13 -> 15505 | C7: =C6*Assumptions!$B$13 -> 28795 | D7: =D6*Assumptions!$B$13 -> 44300 | E7: =E6*Assumptions!$B$13 -> 73095 | F7: =F6*Assumptions!$B$13 -> 104105 | G7: =G6*Assumptions!$B$13 -> 132900 | H7: =H6*Assumptions!$B$13 -> 161695 | I7: =I6*Assumptions!$B$13 -> 192705 | ... AK7: =AK6*Assumptions!$B$13 -> 23791315
A9: ПЕРЕМЕННЫЕ РАСХОДЫ
A10: LLM API | B10: =B6*Assumptions!$B$26 -> 2310 | C10: =C6*Assumptions!$B$26 -> 4290 | D10: =D6*Assumptions!$B$26 -> 6600 | E10: =E6*Assumptions!$B$26 -> 10890 | F10: =F6*Assumptions!$B$26 -> 15510 | G10: =G6*Assumptions!$B$26 -> 19800 | H10: =H6*Assumptions!$B$26 -> 24090 | I10: =I6*Assumptions!$B$26 -> 28710 | ... AK10: =AK6*Assumptions!$B$26 -> 3544530
A11: Эквайринг 2.5% | B11: =B7*Assumptions!$B$27 -> 387.625 | C11: =C7*Assumptions!$B$27 -> 719.875 | D11: =D7*Assumptions!$B$27 -> 1107.5 | E11: =E7*Assumptions!$B$27 -> 1827.375 | F11: =F7*Assumptions!$B$27 -> 2602.625 | G11: =G7*Assumptions!$B$27 -> 3322.5 | H11: =H7*Assumptions!$B$27 -> 4042.375 | I11: =I7*Assumptions!$B$27 -> 4817.625 | ... AK11: =AK7*Assumptions!$B$27 -> 594782.88
A12: Партнёрская комиссия 15% | B12: =B7*Assumptions!$B$28 -> 2325.75 | C12: =C7*Assumptions!$B$28 -> 4319.25 | D12: =D7*Assumptions!$B$28 -> 6645 | E12: =E7*Assumptions!$B$28 -> 10964.25 | F12: =F7*Assumptions!$B$28 -> 15615.75 | G12: =G7*Assumptions!$B$28 -> 19935 | H12: =H7*Assumptions!$B$28 -> 24254.25 | I12: =I7*Assumptions!$B$28 -> 28905.75 | ... AK12: =AK7*Assumptions!$B$28 -> 3568697.2
A13: Итого переменных | B13: =SUM(B10:B12) -> 5023.375 | C13: =SUM(C10:C12) -> 9329.125 | D13: =SUM(D10:D12) -> 14352.5 | E13: =SUM(E10:E12) -> 23681.625 | F13: =SUM(F10:F12) -> 33728.375 | G13: =SUM(G10:G12) -> 43057.5 | H13: =SUM(H10:H12) -> 52386.625 | I13: =SUM(I10:I12) -> 62433.375 | ... AK13: =SUM(AK10:AK12) -> 7708010.1
A14: Gross Profit | B14: =B7-B13 -> 10481.625 | C14: =C7-C13 -> 19465.875 | D14: =D7-D13 -> 29947.5 | E14: =E7-E13 -> 49413.375 | F14: =F7-F13 -> 70376.625 | G14: =G7-G13 -> 89842.5 | H14: =H7-H13 -> 109308.38 | I14: =I7-I13 -> 130271.62 | ... AK14: =AK7-AK13 -> 16083305
A15: Gross margin % | B15: =IF(B7=0,0,B14/B7) -> 0.6760158 | C15: =IF(C7=0,0,C14/C7) -> 0.6760158 | D15: =IF(D7=0,0,D14/D7) -> 0.6760158 | E15: =IF(E7=0,0,E14/E7) -> 0.6760158 | F15: =IF(F7=0,0,F14/F7) -> 0.6760158 | G15: =IF(G7=0,0,G14/G7) -> 0.6760158 | H15: =IF(H7=0,0,H14/H7) -> 0.6760158 | I15: =IF(I7=0,0,I14/I7) -> 0.6760158 | ... AK15: =IF(AK7=0,0,AK14/AK7) -> 0.6760158
A17: ФИКС. РАСХОДЫ (по году)
A18: Инфраструктура | B18: =Assumptions!$B$39 -> 57000 | C18: =Assumptions!$B$39 -> 57000 | D18: =Assumptions!$B$39 -> 57000 | E18: =Assumptions!$B$39 -> 57000 | F18: =Assumptions!$B$39 -> 57000 | G18: =Assumptions!$B$39 -> 57000 | H18: =Assumptions!$B$39 -> 57000 | I18: =Assumptions!$B$39 -> 57000 | ... M18: =Assumptions!$B$39 -> 57000 | N18: =Assumptions!$C$39 -> 197000 | O18: =Assumptions!$C$39 -> 197000 | P18: =Assumptions!$C$39 -> 197000 | Q18: =Assumptions!$C$39 -> 197000 | R18: =Assumptions!$C$39 -> 197000 | S18: =Assumptions!$C$39 -> 197000 | T18: =Assumptions!$C$39 -> 197000 | U18: =Assumptions!$C$39 -> 197000 | ... Y18: =Assumptions!$C$39 -> 197000 | Z18: =Assumptions!$D$39 -> 615000 | AA18: =Assumptions!$D$39 -> 615000 | AB18: =Assumptions!$D$39 -> 615000 | AC18: =Assumptions!$D$39 -> 615000 | AD18: =Assumptions!$D$39 -> 615000 | AE18: =Assumptions!$D$39 -> 615000 | AF18: =Assumptions!$D$39 -> 615000 | AG18: =Assumptions!$D$39 -> 615000 | ... AK18: =Assumptions!$D$39 -> 615000
A19: ФОТ + взносы | B19: =Assumptions!$B$45 -> 64000 | C19: =Assumptions!$B$45 -> 64000 | D19: =Assumptions!$B$45 -> 64000 | E19: =Assumptions!$B$45 -> 64000 | F19: =Assumptions!$B$45 -> 64000 | G19: =Assumptions!$B$45 -> 64000 | H19: =Assumptions!$B$45 -> 64000 | I19: =Assumptions!$B$45 -> 64000 | ... M19: =Assumptions!$B$45 -> 64000 | N19: =Assumptions!$C$45 -> 290000 | O19: =Assumptions!$C$45 -> 290000 | P19: =Assumptions!$C$45 -> 290000 | Q19: =Assumptions!$C$45 -> 290000 | R19: =Assumptions!$C$45 -> 290000 | S19: =Assumptions!$C$45 -> 290000 | T19: =Assumptions!$C$45 -> 290000 | U19: =Assumptions!$C$45 -> 290000 | ... Y19: =Assumptions!$C$45 -> 290000 | Z19: =Assumptions!$D$45 -> 1860000 | AA19: =Assumptions!$D$45 -> 1860000 | AB19: =Assumptions!$D$45 -> 1860000 | AC19: =Assumptions!$D$45 -> 1860000 | AD19: =Assumptions!$D$45 -> 1860000 | AE19: =Assumptions!$D$45 -> 1860000 | AF19: =Assumptions!$D$45 -> 1860000 | AG19: =Assumptions!$D$45 -> 1860000 | ... AK19: =Assumptions!$D$45 -> 1860000
A20: G&A + резерв | B20: =Assumptions!$B$62 -> 45950 | C20: =Assumptions!$B$62 -> 45950 | D20: =Assumptions!$B$62 -> 45950 | E20: =Assumptions!$B$62 -> 45950 | F20: =Assumptions!$B$62 -> 45950 | G20: =Assumptions!$B$62 -> 45950 | H20: =Assumptions!$B$62 -> 45950 | I20: =Assumptions!$B$62 -> 45950 | ... M20: =Assumptions!$B$62 -> 45950 | N20: =Assumptions!$C$62 -> 320450 | O20: =Assumptions!$C$62 -> 320450 | P20: =Assumptions!$C$62 -> 320450 | Q20: =Assumptions!$C$62 -> 320450 | R20: =Assumptions!$C$62 -> 320450 | S20: =Assumptions!$C$62 -> 320450 | T20: =Assumptions!$C$62 -> 320450 | U20: =Assumptions!$C$62 -> 320450 | ... Y20: =Assumptions!$C$62 -> 320450 | Z20: =Assumptions!$D$62 -> 1371150 | AA20: =Assumptions!$D$62 -> 1371150 | AB20: =Assumptions!$D$62 -> 1371150 | AC20: =Assumptions!$D$62 -> 1371150 | AD20: =Assumptions!$D$62 -> 1371150 | AE20: =Assumptions!$D$62 -> 1371150 | AF20: =Assumptions!$D$62 -> 1371150 | AG20: =Assumptions!$D$62 -> 1371150 | ... AK20: =Assumptions!$D$62 -> 1371150
A21: Итого фиксированных | B21: =SUM(B18:B20) -> 166950 | C21: =SUM(C18:C20) -> 166950 | D21: =SUM(D18:D20) -> 166950 | E21: =SUM(E18:E20) -> 166950 | F21: =SUM(F18:F20) -> 166950 | G21: =SUM(G18:G20) -> 166950 | H21: =SUM(H18:H20) -> 166950 | I21: =SUM(I18:I20) -> 166950 | ... AK21: =SUM(AK18:AK20) -> 3846150
A23: НАЛОГИ
A24: УСН 6% | B24: =B7*Assumptions!$B$66 -> 930.3 | C24: =C7*Assumptions!$B$66 -> 1727.7 | D24: =D7*Assumptions!$B$66 -> 2658 | E24: =E7*Assumptions!$B$66 -> 4385.7 | F24: =F7*Assumptions!$B$66 -> 6246.3 | G24: =G7*Assumptions!$B$66 -> 7974 | H24: =H7*Assumptions!$B$66 -> 9701.7 | I24: =I7*Assumptions!$B$66 -> 11562.3 | ... AK24: =AK7*Assumptions!$B$66 -> 1427478.9
A25: НДС 5% (от Y3) | B25: =0 -> 0 | C25: =0 -> 0 | D25: =0 -> 0 | E25: =0 -> 0 | F25: =0 -> 0 | G25: =0 -> 0 | H25: =0 -> 0 | I25: =0 -> 0 | ... Y25: =0 -> 0 | Z25: =Z7*Assumptions!$B$68 -> 352960.25 | AA25: =AA7*Assumptions!$B$68 -> 429045.5 | AB25: =AB7*Assumptions!$B$68 -> 505020 | AC25: =AC7*Assumptions!$B$68 -> 581105.25 | AD25: =AD7*Assumptions!$B$68 -> 657190.5 | AE25: =AE7*Assumptions!$B$68 -> 733275.75 | AF25: =AF7*Assumptions!$B$68 -> 809250.25 | AG25: =AG7*Assumptions!$B$68 -> 885335.5 | ... AK25: =AK7*Assumptions!$B$68 -> 1189565.8
A26: Итого налогов | B26: =B24+B25 -> 930.3 | C26: =C24+C25 -> 1727.7 | D26: =D24+D25 -> 2658 | E26: =E24+E25 -> 4385.7 | F26: =F24+F25 -> 6246.3 | G26: =G24+G25 -> 7974 | H26: =H24+H25 -> 9701.7 | I26: =I24+I25 -> 11562.3 | ... AK26: =AK24+AK25 -> 2617044.6
A28: ИТОГИ
A29: Всего расходов | B29: =B13+B21+B26 -> 172903.67 | C29: =C13+C21+C26 -> 178006.83 | D29: =D13+D21+D26 -> 183960.5 | E29: =E13+E21+E26 -> 195017.33 | F29: =F13+F21+F26 -> 206924.67 | G29: =G13+G21+G26 -> 217981.5 | H29: =H13+H21+H26 -> 229038.33 | I29: =I13+I21+I26 -> 240945.67 | ... AK29: =AK13+AK21+AK26 -> 14171205
A30: EBITDA | B30: =B7-B29 -> -157398.67 | C30: =C7-C29 -> -149211.83 | D30: =D7-D29 -> -139660.5 | E30: =E7-E29 -> -121922.32 | F30: =F7-F29 -> -102819.68 | G30: =G7-G29 -> -85081.5 | H30: =H7-H29 -> -67343.325 | I30: =I7-I29 -> -48240.675 | ... AK30: =AK7-AK29 -> 9620110.2
A31: EBITDA margin | B31: =IF(B7=0,0,B30/B7) -> -10.151479 | C31: =IF(C7=0,0,C30/C7) -> -5.1818658 | D31: =IF(D7=0,0,D30/D7) -> -3.1526072 | E31: =IF(E7=0,0,E30/E7) -> -1.6679982 | F31: =IF(F7=0,0,F30/F7) -> -0.98765357 | G31: =IF(G7=0,0,G30/G7) -> -0.64019187 | H31: =IF(H7=0,0,H30/H7) -> -0.41648366 | I31: =IF(I7=0,0,I30/I7) -> -0.25033432 | ... AK31: =IF(AK7=0,0,AK30/AK7) -> 0.40435387
A33: Грант + кэш | B33: =Assumptions!$B$72+B30 -> 842601.32 | C33: =B33+C30 -> 693389.5 | D33: =C33+D30 -> 553729 | E33: =D33+E30 -> 431806.67 | F33: =E33+F30 -> 328987 | G33: =F33+G30 -> 243905.5 | H33: =G33+H30 -> 176562.17 | I33: =H33+I30 -> 128321.5 | J33: =I33+J30 -> 97819 | ... AK33: =AJ33+AK30 -> 74927651

Sheet Annual Summary
A1: ГОДОВАЯ СВОДКА
A3: Показатель | B3: Год 1 | C3: Год 2 | D3: Год 3 | E3: Сумма 3 года
A4: Клиенты на конец года | B4: ='P&L Monthly'!M6 -> 400 | C4: ='P&L Monthly'!Y6 -> 2500 | D4: ='P&L Monthly'!AK6 -> 10741 | E4: =D4 -> 10741
A5: Выручка | B5: =SUM('P&L Monthly'!B7:M7) -> 2968100 | C5: =SUM('P&L Monthly'!N7:Y7) -> 40866750 | D5: =SUM('P&L Monthly'!Z7:AK7) -> 185103120 | E5: =SUM(B5:D5) -> 228937970
A6: LLM API | B6: =SUM('P&L Monthly'!B10:M10) -> 442200 | C6: =SUM('P&L Monthly'!N10:Y10) -> 6088500 | D6: =SUM('P&L Monthly'!Z10:AK10) -> 27577440 | E6: =SUM(B6:D6) -> 34108140
A7: Эквайринг | B7: =SUM('P&L Monthly'!B11:M11) -> 74202.5 | C7: =SUM('P&L Monthly'!N11:Y11) -> 1021668.8 | D7: =SUM('P&L Monthly'!Z11:AK11) -> 4627578 | E7: =SUM(B7:D7) -> 5723449.2
A8: Партнёрская комиссия | B8: =SUM('P&L Monthly'!B12:M12) -> 445215 | C8: =SUM('P&L Monthly'!N12:Y12) -> 6130012.5 | D8: =SUM('P&L Monthly'!Z12:AK12) -> 27765468 | E8: =SUM(B8:D8) -> 34340696
A9: Итого переменных | B9: =SUM('P&L Monthly'!B13:M13) -> 961617.5 | C9: =SUM('P&L Monthly'!N13:Y13) -> 13240181 | D9: =SUM('P&L Monthly'!Z13:AK13) -> 59970486 | E9: =SUM(B9:D9) -> 74172285
A10: Gross Profit | B10: =SUM('P&L Monthly'!B14:M14) -> 2006482.5 | C10: =SUM('P&L Monthly'!N14:Y14) -> 27626569 | D10: =SUM('P&L Monthly'!Z14:AK14) -> 125132634 | E10: =SUM(B10:D10) -> 1.5476569e+08
A11: Инфраструктура | B11: =SUM('P&L Monthly'!B18:M18) -> 684000 | C11: =SUM('P&L Monthly'!N18:Y18) -> 2364000 | D11: =SUM('P&L Monthly'!Z18:AK18) -> 7380000 | E11: =SUM(B11:D11) -> 10428000
A12: ФОТ + взносы | B12: =SUM('P&L Monthly'!B19:M19) -> 768000 | C12: =SUM('P&L Monthly'!N19:Y19) -> 3480000 | D12: =SUM('P&L Monthly'!Z19:AK19) -> 22320000 | E12: =SUM(B12:D12) -> 26568000
A13: G&A + резерв | B13: =SUM('P&L Monthly'!B20:M20) -> 551400 | C13: =SUM('P&L Monthly'!N20:Y20) -> 3845400 | D13: =SUM('P&L Monthly'!Z20:AK20) -> 16453800 | E13: =SUM(B13:D13) -> 20850600
A14: Налоги (УСН + НДС) | B14: =SUM('P&L Monthly'!B26:M26) -> 178086 | C14: =SUM('P&L Monthly'!N26:Y26) -> 2452005 | D14: =SUM('P&L Monthly'!Z26:AK26) -> 20361343 | E14: =SUM(B14:D14) -> 22991434
A15: ВСЕГО РАСХОДОВ | B15: =SUM('P&L Monthly'!B29:M29) -> 3143103.5 | C15: =SUM('P&L Monthly'!N29:Y29) -> 25381586 | D15: =SUM('P&L Monthly'!Z29:AK29) -> 1.2648563e+08 | E15: =SUM(B15:D15) -> 1.5501032e+08
A16: EBITDA | B16: =SUM('P&L Monthly'!B30:M30) -> -175003.5 | C16: =SUM('P&L Monthly'!N30:Y30) -> 15485164 | D16: =SUM('P&L Monthly'!Z30:AK30) -> 58617491 | E16: =SUM(B16:D16) -> 73927651
A19: ПРОИЗВОДНЫЕ МЕТРИКИ
A20: Gross margin % | B20: =IF(B5=0,0,B10/B5) -> 0.6760158 | C20: =IF(C5=0,0,C10/C5) -> 0.6760158 | D20: =IF(D5=0,0,D10/D5) -> 0.6760158
A21: EBITDA margin % | B21: =IF(B5=0,0,B16/B5) -> -0.058961457 | C21: =IF(C5=0,0,C16/C5) -> 0.37891841 | D21: =IF(D5=0,0,D16/D5) -> 0.31667479
A22: Рост выручки YoY | B22: N/A | C22: =IF(B5=0,0,(C5/B5)-1) -> 12.768657 | D22: =IF(C5=0,0,(D5/C5)-1) -> 3.5294309
A23: Rule of 40 (рост + EBITDA margin) | B23: N/A | C23: =((C5/B5)-1)*100+(C16/C5)*100 -> 1314.7575 | D23: =((D5/C5)-1)*100+(D16/D5)*100 -> 384.61057
A25: ARPU (среднее за год) | B25: =B5/12/((B4+IF(COLUMN()=2,0,A4))/2) -> 1236.7083 | C25: =C5/12/((C4+IF(COLUMN()=2,0,B4))/2) -> 2348.6638 | D25: =D5/12/((D4+IF(COLUMN()=2,0,C4))/2) -> 2329.9237

Sheet Sensitivity
A1: SENSITIVITY ANALYSIS — РЫЧАГИ ОПТИМИЗАЦИИ
A2: Каждый рычаг применим самостоятельно. Сценарий 'Все рычаги' — комбинированный эффект.
A4: ТРИ РЫЧАГА ОПТИМИЗАЦИИ
A5: Рычаг | B5: Эффект | C5: Параметр | D5: Y1 экономия | E5: Y2 экономия | F5: Y3 экономия
A6: A. IT-аккредитация | B6: Взносы МСП 30%/15% → IT 15%/7,6% (правила 2026) | C6: Снижение взносов (расчёт в Assumptions) | D6: =Assumptions!B154 -> 90000 | E6: =Assumptions!C154 -> 365755.5 | F6: =Assumptions!D154 -> 731511
A7: B. LLM-оптимизация | B7: Caching + routing + рос. модели | C7: 330 ₽ → 200 ₽/клиент | D7: ='Annual Summary'!B6*(1-200/330) -> 174200 | E7: ='Annual Summary'!C6*(1-200/330) -> 2398500 | F7: ='Annual Summary'!D6*(1-200/330) -> 10863840
A8: C. Реестр росс. ПО | B8: НДС 5% → 0% при включении в реестр | C8: Освобождение от НДС | D8: =0 -> 0 | E8: =0 -> 0 | F8: ='Annual Summary'!D5*Assumptions!B68 -> 9255156
A9: ВСЕГО (все рычаги) | D9: =SUM(D6:D8) -> 264200 | E9: =SUM(E6:E8) -> 2764255.5 | F9: =SUM(F6:F8) -> 20850507
A11: EBITDA ПО СЦЕНАРИЯМ
A12: Сценарий | B12: Y1 EBITDA | C12: Y2 EBITDA | D12: Y3 EBITDA | E12: Кумулятив 3 года | F12: Δ к Base
A13: Base case (текущая модель) | B13: ='Annual Summary'!B16 -> -175003.5 | C13: ='Annual Summary'!C16 -> 15485164 | D13: ='Annual Summary'!D16 -> 58617491 | E13: =SUM(B13:D13) -> 73927651 | F13: 0
A14: + A: IT-аккредитация | B14: =B13+D6 -> -85003.5 | C14: =C13+E6 -> 15850919 | D14: =D13+F6 -> 59349002 | E14: =SUM(B14:D14) -> 75114918 | F14: =E14-E13 -> 1187266.5
A15: + B: LLM-оптимизация | B15: =B13+D7 -> -803.5 | C15: =C13+E7 -> 17883664 | D15: =D13+F7 -> 69481331 | E15: =SUM(B15:D15) -> 87364191 | F15: =E15-E13 -> 13436540
A16: + C: Реестр росс. ПО | B16: =B13+D8 -> -175003.5 | C16: =C13+E8 -> 15485164 | D16: =D13+F8 -> 67872647 | E16: =SUM(B16:D16) -> 83182807 | F16: =E16-E13 -> 9255156
A17: ВСЕ РЫЧАГИ ВМЕСТЕ | B17: =B13+D9 -> 89196.5 | C17: =C13+E9 -> 18249419 | D17: =D13+F9 -> 79467998 | E17: =SUM(B17:D17) -> 97806614 | F17: =E17-E13 -> 23878962
A19: EBITDA MARGIN % ПО СЦЕНАРИЯМ
A20: Сценарий | B20: Y1 | C20: Y2 | D20: Y3 | E20: Бенчмарк
A21: Base case | B21: =B13/'Annual Summary'!B5 -> -0.058961457 | C21: =C13/'Annual Summary'!C5 -> 0.37891841 | D21: =D13/'Annual Summary'!D5 -> 0.31667479 | E21: Atlassian: 25%
A22: + A: IT-аккредитация | B22: =B14/'Annual Summary'!B5 -> -0.028639028 | C22: =C14/'Annual Summary'!C5 -> 0.38786836 | D22: =D14/'Annual Summary'!D5 -> 0.3206267
A23: + B: LLM-оптимизация | B23: =B15/'Annual Summary'!B5 -> -0.0002707119 | C23: =C15/'Annual Summary'!C5 -> 0.43760915 | D23: =D15/'Annual Summary'!D5 -> 0.37536553
A24: + C: Реестр росс. ПО | B24: =B16/'Annual Summary'!B5 -> -0.058961457 | C24: =C16/'Annual Summary'!C5 -> 0.37891841 | D24: =D16/'Annual Summary'!D5 -> 0.36667479
A25: ВСЕ РЫЧАГИ ВМЕСТЕ | B25: =B17/'Annual Summary'!B5 -> 0.030051717 | C25: =C17/'Annual Summary'!C5 -> 0.4465591 | D25: =D17/'Annual Summary'!D5 -> 0.42931744 | E25: Veeva (top): 40%
A27: 📌 ИТОГИ ДЛЯ ПИТЧА
A28: • Все три рычага реалистично применимы в течение Y2-Y3 (требуют документов и времени, но не доп.инвестиций)
A29: • При полной оптимизации EBITDA Y3 margin приближается к топ-квартилю vertical SaaS (40%+)
A30: • Кумулятивная EBITDA за 3 года вырастает без увеличения выручки — чистая операционная эффективность
A31: • Это можно показать инвестору как 'консервативный сценарий + три upside'
A34: PLAN B — СТРЕСС-ТЕСТ: ЗАДЕРЖКА С РЕЕСТРОМ РОССИЙСКОГО ПО
A35: Базовая модель предполагает включение в Реестр росс. ПО на M3. Если это не происходит — НДС начисляется в Y2 с момента, когда кум. выручка превысит 20 млн ₽.
A37: ХРОНОЛОГИЯ: КУМУЛЯТИВНАЯ ВЫРУЧКА Y2 ПРОТИВ ПОРОГА 20 МЛН ₽
A38: Месяц | B38: Выручка/мес | C38: Кум. выручка Y2 | D38: Превышение порога? | E38: НДС начисляется?
A39: M13 | B39: 1273625 | C39: 1273625 | D39: нет | E39: нет
A40: M14 | B40: 1661250 | C40: 2934875 | D40: нет | E40: нет
A41: M15 | B41: 2048875 | C41: 4983750 | D41: нет | E41: нет
A42: M16 | B42: 2436500 | C42: 7420250 | D42: нет | E42: нет
A43: M17 | B43: 2824125 | C43: 10244375 | D43: нет | E43: нет
A44: M18 | B44: 3211750 | C44: 13456125 | D44: нет | E44: нет
A45: M19 | B45: 3599375 | C45: 17055500 | D45: нет | E45: нет
A46: M20 | B46: 3987000 | C46: 21042500 | D46: ДА | E46: нет (превышение в этом мес.)
A47: M21 | B47: 4374625 | C47: 25417125 | D47: ДА | E47: ДА: 218,731 ₽
...

Sheet Investor View
A1: КЛЮЧЕВЫЕ МЕТРИКИ ДЛЯ ИНВЕСТОРА
A3: Метрика | B3: Значение | C3: Комментарий
A4: Месяц break-even (EBITDA ≥ 0) | B4: =MATCH(TRUE(),INDEX('P&L Monthly'!B30:AM30>0,0),0) -> 10 | C4: Целевой M9
A5: Минимальный кэш-баланс | B5: =MIN('P&L Monthly'!B33:AM33) -> 97819 | C5: Должен быть > 0 → грант покрывает
A6: Кэш на конец Y1 | B6: ='P&L Monthly'!M33 -> 824996.5
A7: Выручка Y3 | B7: ='Annual Summary'!D5 -> 185103120
A8: EBITDA Y3 | B8: ='Annual Summary'!D16 -> 58617491
A9: EBITDA margin Y3 | B9: ='Annual Summary'!D16/'Annual Summary'!D5 -> 0.31667479
A10: Кумулятивная EBITDA 3 года | B10: ='Annual Summary'!E16 -> 73927651
A12: СТРУКТУРА ARPU
A13: Blended ARPU | B13: =Assumptions!$B$13 -> 2215 | C13: Средневзвешенная по тарифам
A14: Переменные расходы на клиента | B14: =Assumptions!$B$26+Assumptions!$B$13*Assumptions!$B$27+Assumptions!$B$13*Assumptions!$B$28 -> 717.625 | C14: LLM + эквайринг + партнёр
A15: Gross margin на клиента | B15: =(Assumptions!$B$13-B14)/Assumptions!$B$13 -> 0.6760158 | C15: Целевой ≥75%
A16: LTV (упрощённо, ARPU/churn × GM) | B16: =(Assumptions!$B$13/Assumptions!$B$22)*(Assumptions!$B$13-B14)/Assumptions!$B$13 -> 37434.375 | C16: При churn 4%/мес
A18: 📌 Все цифры обновляются автоматически при изменении предпосылок на листе Assumptions
